<?xml version="1.0" ?>
<!-- =================================================================================== -->
<!-- |    This document was autogenerated by xacro from ros2_mara_ws/src/robotiq_modular_gripper/robotiq_140_gripper_description/urdf/robotiq_140_world.urdf.xacro | -->
<!-- |    EDITING THIS FILE BY HAND IS NOT RECOMMENDED                                 | -->
<!-- =================================================================================== -->
<robot name="robotiq_gripper">
 
  <!-- Gripper -->
  <!-- robotiq_140_base_link -->
  <link name="robotiq_140_robotiq_2f_base_link">
    <inertial>
      <origin rpy="0 0 0" xyz="-0.00013 0.00011 0.03284"/>
      <mass value="0.52954"/>
      <inertia ixx="573495E-9" ixy="-554E-9" ixz="2628E-9"
               iyy="681780E-9" iyz="607E-9" izz="483281E-9" />
    </inertial>
    <visual>
      <origin rpy="0 0 0" xyz="0 0 0"/>
      <geometry>
        <mesh filename="./robotiq_140_gripper_description/meshes/robotiq_2f_140_base.dae" scale="0.001 0.001 0.001"/>
      </geometry>
      <material name="Gazebo/Black">
        <color rgba="0.1 0.1 0.1 1"/>
      </material>
    </visual>
    <collision>
      <origin rpy="0 0 0" xyz="0 0 0"/>
      <geometry>
        <mesh filename="package://robotiq_140_gripper_description/meshes/robotiq_2f_140_base.dae" scale="0.001 0.001 0.001"/>
      </geometry>
    </collision>
  </link>
  <gazebo reference="robotiq_140_robotiq_2f_base_link">
    <material>Gazebo/Black</material>
    <selfCollide>True</selfCollide>
  </gazebo>
  
  <!-- robotiq_85_left_knuckle_link -->
  <link name="robotiq_140_left_outer_knuckle">
    <inertial>
      <origin rpy="0 0 0" xyz="0.01616 0 -0.00133"/>
      <mass value="0.0131"/>
      <inertia ixx="325.5E-9" ixy="0" ixz="197.94E-9" iyy="2306.36E-9" iyz="0" izz="2176E-9"/>
    </inertial>
    <visual>
      <origin rpy="0 0 0" xyz="0 0 0"/>
      <geometry>
        <mesh filename="package://robotiq_140_gripper_description/meshes/robotiq_2f_140_left_outer_knuckle.dae" scale="0.001 0.001 0.001"/>
      </geometry>
      <material name="">
        <color rgba="0.792156862745098 0.819607843137255 0.933333333333333 1"/>
      </material>
    </visual>
    <collision>
      <origin rpy="0 0 0" xyz="0 0 0"/>
      <geometry>
        <mesh filename="package://robotiq_140_gripper_description/meshes/robotiq_2f_140_left_outer_knuckle.dae" scale="0.001 0.001 0.001"/>
      </geometry>
    </collision>
  </link>
  <gazebo reference="robotiq_140_left_outer_knuckle">
    <material>Gazebo/Grey</material>
    <selfCollide>True</selfCollide>
  </gazebo>
  <!-- robotiq_85_right_knuckle_link -->
  <link name="robotiq_140_right_outer_knuckle">
    <inertial>
      <origin rpy="0 0 0" xyz="-0.01616 0 -0.00133"/>
      <mass value="0.0131"/>
      <inertia ixx="325.5E-9" ixy="0" ixz="-197.94E-9" iyy="2306.36E-9" iyz="0" izz="2176E-9"/>
    </inertial>
    <visual>
      <origin rpy="0 0 0" xyz="0 0 0"/>
      <geometry>
        <mesh filename="package://robotiq_140_gripper_description/meshes/robotiq_2f_140_right_outer_knuckle.dae" scale="0.001 0.001 0.001"/>
      </geometry>
      <material name="">
        <color rgba="0.792156862745098 0.819607843137255 0.933333333333333 1"/>
      </material>
    </visual>
    <collision>
      <origin rpy="0 0 0" xyz="0 0 0"/>
      <geometry>
        <mesh filename="package://robotiq_140_gripper_description/meshes/robotiq_2f_140_right_outer_knuckle.dae" scale="0.001 0.001 0.001"/>
      </geometry>
    </collision>
  </link>
  <gazebo reference="robotiq_140_right_outer_knuckle">
    <material>Gazebo/Grey</material>
    <selfCollide>True</selfCollide>
  </gazebo>
  <!-- robotiq_85_left_inner_knuckle_link -->
  <link name="robotiq_140_left_inner_knuckle">
    <inertial>
      <origin rpy="0 0 0" xyz="0.03332 0 0.0379"/>
      <mass value="0.04476"/>
      <inertia ixx="28054E-9" ixy="0" ixz="-19174E-9" iyy="39758E-9" iyz="0" izz="23453E-9"/>
    </inertial>
    <visual>
      <origin rpy="0 0 0" xyz="0 0 0"/>
      <geometry>
        <mesh filename="package://robotiq_140_gripper_description/meshes/robotiq_2f_140_left_inner_knuckle.dae" scale="0.001 0.001 0.001"/>
      </geometry>
      <material name="Gazebo/Black">
        <color rgba="0.1 0.1 0.1 1"/>
      </material>
    </visual>
    <collision>
      <origin rpy="0 0 0" xyz="0 0 0"/>
      <geometry>
        <mesh filename="package://robotiq_140_gripper_description/meshes/robotiq_2f_140_left_inner_knuckle.dae" scale="0.001 0.001 0.001"/>
      </geometry>
    </collision>
  </link>
  <gazebo reference="robotiq_140_left_inner_knuckle">
    <material>Gazebo/Black</material>
    <selfCollide>False</selfCollide>
  </gazebo>
  <!-- robotiq_85_right_inner_knuckle_link -->
  <link name="robotiq_140_right_inner_knuckle">
    <inertial>
      <origin rpy="0 0 0" xyz="-0.03332 0 0.0379"/>
      <mass value="0.04476"/>
      <inertia ixx="28054E-9" ixy="0" ixz="19174E-9" iyy="39758E-9" iyz="0" izz="23453E-9"/>
    </inertial>
    <visual>
      <origin rpy="0 0 0" xyz="0 0 0"/>
      <geometry>
        <mesh filename="package://robotiq_140_gripper_description/meshes/robotiq_2f_140_right_inner_knuckle.dae" scale="0.001 0.001 0.001"/>
      </geometry>
      <material name="Gazebo/Black">
        <color rgba="0.1 0.1 0.1 1"/>
      </material>
    </visual>
    <collision>
      <origin rpy="0 0 0" xyz="0 0 0"/>
      <geometry>
        <mesh filename="package://robotiq_140_gripper_description/meshes/robotiq_2f_140_right_inner_knuckle.dae" scale="0.001 0.001 0.001"/>
      </geometry>
    </collision>
  </link>
  <gazebo reference="robotiq_140_right_inner_knuckle">
    <material>Gazebo/Black</material>
    <selfCollide>False</selfCollide>
  </gazebo>
  <!-- robotiq_85_left_finger_link -->
  <link name="robotiq_140_left_inner_finger">
    <inertial>
      <origin rpy="0 0 0" xyz="-0.01563 0 0.02522"/>
      <mass value="0.045"/>
      <inertia ixx="26663E-9" ixy="0" ixz="5579E-9" iyy="28009E-9" iyz="0" izz="4368E-9"/>
    </inertial>
    <visual>
      <origin rpy="0 0 0" xyz="0 0 0"/>
      <geometry>
        <mesh filename="package://robotiq_140_gripper_description/meshes/robotiq_2f_140_left_inner_finger.dae" scale="0.001 0.001 0.001"/>
      </geometry>
      <material name="Gazebo/Black">
        <color rgba="0.1 0.1 0.1 1"/>
      </material>
    </visual>
    <collision>
      <origin rpy="0 0 0" xyz="0 0 0"/>
      <geometry>
        <mesh filename="package://robotiq_140_gripper_description/meshes/robotiq_2f_140_left_inner_finger.dae" scale="0.001 0.001 0.001"/>
      </geometry>_2f
    </collision>
  </link>
  <gazebo reference="robotiq_140_left_inner_finger">
    <material>Gazebo/Black</material>
    <selfCollide>False</selfCollide>
  </gazebo>
  <!-- robotiq_85_right_finger_link -->
  <link name="robotiq_140_right_inner_finger">
    <inertial>
      <origin rpy="0 0 0" xyz="0.01563 0 0.02522"/>
      <mass value="0.045"/>
      <inertia ixx="26663E-9" ixy="0" ixz="-5579E-9" iyy="28009E-9" iyz="0" izz="4368E-9"/>
    </inertial>
    <visual>
      <origin rpy="0 0 0" xyz="0 0 0"/>
      <geometry>
        <mesh filename="package://robotiq_140_gripper_description/meshes/robotiq_2f_140_right_inner_finger.dae" scale="0.001 0.001 0.001"/>
      </geometry>
      <material name="Gazebo/Black">
        <color rgba="0.1 0.1 0.1 1"/>
      </material>
    </visual>
    <collision>
      <origin rpy="0 0 0" xyz="0 0 0"/>
      <geometry>
        <mesh filename="package://robotiq_140_gripper_description/meshes/robotiq_2f_140_right_inner_finger.dae" scale="0.001 0.001 0.001"/>
      </geometry>
    </collision>
  </link>
  <gazebo reference="robotiq_140_right_inner_finger">
    <material>Gazebo/Black</material>
    <selfCollide>False</selfCollide>
  </gazebo>
  <!-- robot -->
  <link name="robotiq_140_left_outer_finger">
    <inertial>
      <origin rpy="0 0 0" xyz="0.01482 0 0.03451"/>
      <mass value="0.07637"/>
      <inertia ixx="45513E-9" ixy="0" ixz="-20691E-9" iyy="52570E-9" iyz="0" izz="17804E-9"/>
    </inertial>
    <visual>
      <origin rpy="0 0 0" xyz="0 0 0"/>
      <geometry>
        <mesh filename="package://robotiq_140_gripper_description/meshes/robotiq_2f_140_left_outer_finger.dae" scale="0.001 0.001 0.001"/>
      </geometry>
      <material name="Gazebo/Black">
        <color rgba="0.1 0.1 0.1 1"/>
      </material>
    </visual>
    <collision>
      <origin rpy="0 0 0" xyz="0 0 0"/>
      <geometry>
        <mesh filename="package://robotiq_140_gripper_description/meshes/robotiq_2f_140_left_outer_finger.dae" scale="0.001 0.001 0.001"/>
      </geometry>
    </collision>
  </link>
  <gazebo reference="robotiq_140_left_outer_finger">
    <material>Gazebo/Black</material>
    <selfCollide>True</selfCollide>
  </gazebo>
  <!-- robot -->
  <link name="robotiq_140_right_outer_finger">
    <inertial>
      <origin rpy="0 0 0" xyz="-0.01482 0 0.03451"/>
      <mass value="0.07637"/>
      <inertia ixx="45513E-9" ixy="0" ixz="20691E-9" iyy="52570E-9" iyz="0" izz="17804E-9"/>
    </inertial>
    <visual>
      <origin rpy="0 0 0" xyz="0 0 0"/>
      <geometry>
        <mesh filename="package://robotiq_140_gripper_description/meshes/robotiq_2f_140_right_outer_finger.dae" scale="0.001 0.001 0.001"/>
      </geometry>
      <material name="Gazebo/Black">
        <color rgba="0.1 0.1 0.1 1"/>
      </material>
    </visual>
    <collision>
      <origin rpy="0 0 0" xyz="0 0 0"/>
      <geometry>
        <mesh filename="package://robotiq_140_gripper_description/meshes/robotiq_2f_140_right_outer_finger.dae" scale="0.001 0.001 0.001"/>
      </geometry>
    </collision>
  </link>
  <gazebo reference="robotiq_140_right_outer_finger">
    <material>Gazebo/Black</material>
    <selfCollide>True</selfCollide>
  </gazebo>
  <!-- robot -->
  <joint name="robotiq_2f_base_to_robotiq_140_left_outer_knuckle" type="revolute">
    <origin rpy="0 0 0" xyz="0.0306 0 0.05466"/>
    <parent link="robotiq_140_robotiq_2f_base_link"/>
    <child link="robotiq_140_left_outer_knuckle"/>
    <axis xyz="0 -1 0"/>
    <limit effort="18.65" lower="0" upper="0.78574722925" velocity="2.0"/>
    <mimic joint="robotiq_140_joint_finger" multiplier="1" offset="0"/>
  </joint>
  <!-- robot -->
  <joint name="robotiq_140_joint_finger" type="revolute">
    <origin rpy="0 0 0" xyz="-0.0306 0 0.05466"/>
    <parent link="robotiq_140_robotiq_2f_base_link"/>
    <child link="robotiq_140_right_outer_knuckle"/>
    <axis xyz="0 1 0"/>
    <limit effort="18.65" lower="0" upper="0.78574722925" velocity="3.54"/>
  </joint>
  <!-- robot -->
  <joint name="robotiq_2f_base_to_robotiq_140_left_inner_knuckle" type="revolute">
    <origin rpy="0 0 0" xyz="0.0127 0 0.06118"/>
    <parent link="robotiq_140_robotiq_2f_base_link"/>
    <child link="robotiq_140_left_inner_knuckle"/>
    <axis xyz="0 -1 0"/>
    <limit effort="18.65" lower="0" upper="0.78574722925" velocity="3.54"/>
    <mimic joint="robotiq_140_joint_finger" multiplier="1" offset="0"/>
  </joint>
  <!-- robot -->
  <joint name="robotiq_2f_base_to_robotiq_140_right_inner_knuckle" type="revolute">
    <origin rpy="0 0 0" xyz="-0.0127 0 0.06118"/>
    <parent link="robotiq_140_robotiq_2f_base_link"/>
    <child link="robotiq_140_right_inner_knuckle"/>
    <axis xyz="0 1 0"/>
    <limit effort="18.65" lower="0" upper="0.78574722925" velocity="3.54"/>
    <mimic joint="robotiq_140_joint_finger" multiplier="1" offset="0"/>
  </joint>
  <!-- robot -->
  <joint name="robotiq_140_left_outer_knuckle_to_finger" type="fixed">
    <origin rpy="0 0 0" xyz="0.03142 0 -0.00453"/>
    <parent link="robotiq_140_left_outer_knuckle"/>
    <child link="robotiq_140_left_outer_finger"/>
  </joint>
  <!-- robot -->
  <joint name="robotiq_140_right_outer_knuckle_to_finger" type="fixed">
    <origin rpy="0 0 0" xyz="-0.03142 0 -0.00453"/>
    <parent link="robotiq_140_right_outer_knuckle"/>
    <child link="robotiq_140_right_outer_finger"/>
  </joint>
  <!-- robot -->
  <joint name="robotiq_140_left_outer_finger_to_inner" type="revolute">
    <origin rpy="0 0 0" xyz="0.03543 0 0.0789"/>
    <parent link="robotiq_140_left_outer_finger"/>
    <child link="robotiq_140_left_inner_finger"/>
    <axis xyz="0 1 0"/>
    <limit effort="18.65" lower="0" upper="0.78574722925" velocity="3.54"/>
    <mimic joint="robotiq_140_joint_finger" multiplier="1" offset="0"/>
  </joint>
  <!-- robot -->
  <joint name="robotiq_140_right_outer_finger_to_inner" type="revolute">
    <origin rpy="0 0 0" xyz="-0.03543 0 0.0789"/>
    <parent link="robotiq_140_right_outer_finger"/>
    <child link="robotiq_140_right_inner_finger"/>
    <axis xyz="0 -1 0"/>
    <limit effort="18.65" lower="0" upper="0.78574722925" velocity="3.54"/>
    <mimic joint="robotiq_140_joint_finger" multiplier="1" offset="0"/>
  </joint>
</robot>
